Workbook

Sheet Sheet1
A3: Row Labels | B3: Sum of Capped net adjusted incurred claim (HINT: Capped net adjusted incurred claim = net inflation adjusted claim capped at policy limit) | C3: Count of Capped net adjusted incurred claim (HINT: Capped net adjusted incurred claim = net inflation adjusted claim capped at policy limit)2
A4: 2018 | B4: 6428231.6 | C4: 10
A5: 2019 | B5: 10365189 | C5: 17
A6: 2020 | B6: 12073242 | C6: 20
A7: 2021 | B7: 11966327 | C7: 20
A8: 2022 | B8: 15005684 | C8: 17
A9: 2023 | B9: 7445877.4 | C9: 16
A10: Grand Total | B10: 63284551 | C10: 100

Sheet Claims Data
A1: Claim ID | B1: Date of Claim | C1: Type of Claim | D1: Claim Incurred ($) | E1: Claim Status | F1: Gross claim amount (HINT: Gross claim amount = Claim incurred + deductible) | G1: Policy Limits ($) | H1: Deductible ($) | I1: Cause of Loss | J1: Location | K1: Insured Party | L1: Gross Tonnage | M1: Prior Claims History | N1: Inflation Index | O1: Gross inflation adjusted claim (HINT: Gross inflation adjusted claim = gross claim * inflation index) | P1: Net inflation adjusted claim (HINT: Net inflation adjusted claim = Gross inflation adjusted claim - deductible) | Q1: Capped net adjusted incurred claim (HINT: Capped net adjusted incurred claim = net inflation adjusted claim capped at policy limit) | R1: Attritional claim flag - (set equal to 1 if claim is less than 1m, otherwise 0) | S1: Year
A2: CLM-00001 | B2: 43664 | C2: Collision Liability | D2: 737423.28 | E2: Closed | F2: =D2+H2 -> 749769.2 | G2: 5000000 | H2: 12345.92 | I2: Human Error | J2: Indian Ocean | K2: Company 9 | L2: =IF(C2="Cargo Liability",RANDBETWEEN(10000,80000),IF(C2="Collision Liability",RANDBETWEEN(20000,100000),IF(C2="Environmental Pollution",RANDBETWEEN(50000,120000),IF(C2="Damage to Other Vessels",RANDBETWEEN(15000,90000),IF(C2="Injury to Third Parties",RANDBETWEEN(5000,60000)))))) -> 95613 | M2: 4 | N2: =IF(YEAR(B2)=2023, 1.03, IF(YEAR(B2)=2022, 1.0506, IF(YEAR(B2)=2021, 1.071612, IF(YEAR(B2)=2020, 1.10376036, IF(YEAR(B2)=2019, 1.1479107744, IF(YEAR(B2)=2018, 1.20530631312, 1)))))) -> 1.1479108 | O2: =F2*N2 -> 860668.14 | P2: =O2 - H2 -> 848322.22 | Q2: =MIN(P2,G2) -> 848322.22 | R2: =IF(Q2<1000000,1,0) -> 1 | S2: =YEAR(B2) -> 2019
A3: CLM-00002 | B3: 43978 | C3: Cargo Liability | D3: 315189.74 | E3: Closed | F3: =D3+H3 -> 348906.5 | G3: 5000000 | H3: 33716.76 | I3: Technical Failure | J3: Atlantic Ocean | K3: Company 4 | L3: =IF(C3="Cargo Liability",RANDBETWEEN(10000,80000),IF(C3="Collision Liability",RANDBETWEEN(20000,100000),IF(C3="Environmental Pollution",RANDBETWEEN(50000,120000),IF(C3="Damage to Other Vessels",RANDBETWEEN(15000,90000),IF(C3="Injury to Third Parties",RANDBETWEEN(5000,60000)))))) -> 25912 | M3: 6 | N3: =IF(YEAR(B3)=2023, 1.03, IF(YEAR(B3)=2022, 1.0506, IF(YEAR(B3)=2021, 1.071612, IF(YEAR(B3)=2020, 1.10376036, IF(YEAR(B3)=2019, 1.1479107744, IF(YEAR(B3)=2018, 1.20530631312, 1)))))) -> 1.1037604 | O3: =F3*N3 -> 385109.16 | P3: =O3 - H3 -> 351392.4 | Q3: =MIN(P3,G3) -> 351392.4 | R3: =IF(Q3<1000000,1,0) -> 1 | S3: =YEAR(B3) -> 2020
A4: CLM-00003 | B4: 43427 | C4: Damage to Other Vessels | D4: 678364.99 | E4: Closed | F4: =D4+H4 -> 712761.9 | G4: 5000000 | H4: 34396.91 | I4: Criminal Activity | J4: Mediterranean Sea | K4: Company 2 | L4: =IF(C4="Cargo Liability",RANDBETWEEN(10000,80000),IF(C4="Collision Liability",RANDBETWEEN(20000,100000),IF(C4="Environmental Pollution",RANDBETWEEN(50000,120000),IF(C4="Damage to Other Vessels",RANDBETWEEN(15000,90000),IF(C4="Injury to Third Parties",RANDBETWEEN(5000,60000)))))) -> 85577 | M4: 3 | N4: =IF(YEAR(B4)=2023, 1.03, IF(YEAR(B4)=2022, 1.0506, IF(YEAR(B4)=2021, 1.071612, IF(YEAR(B4)=2020, 1.10376036, IF(YEAR(B4)=2019, 1.1479107744, IF(YEAR(B4)=2018, 1.20530631312, 1)))))) -> 1.2053063 | O4: =F4*N4 -> 859096.42 | P4: =O4 - H4 -> 824699.51 | Q4: =MIN(P4,G4) -> 824699.51 | R4: =IF(Q4<1000000,1,0) -> 1 | S4: =YEAR(B4) -> 2018
A5: CLM-00004 | B5: 44201 | C5: Environmental Pollution | D5: 203840.58 | E5: Open | F5: =D5+H5 -> 215544.46 | G5: 5000000 | H5: 11703.88 | I5: Natural Disaster | J5: Pacific Ocean | K5: Company 17 | L5: =IF(C5="Cargo Liability",RANDBETWEEN(10000,80000),IF(C5="Collision Liability",RANDBETWEEN(20000,100000),IF(C5="Environmental Pollution",RANDBETWEEN(50000,120000),IF(C5="Damage to Other Vessels",RANDBETWEEN(15000,90000),IF(C5="Injury to Third Parties",RANDBETWEEN(5000,60000)))))) -> 65770 | M5: 7 | N5: =IF(YEAR(B5)=2023, 1.03, IF(YEAR(B5)=2022, 1.0506, IF(YEAR(B5)=2021, 1.071612, IF(YEAR(B5)=2020, 1.10376036, IF(YEAR(B5)=2019, 1.1479107744, IF(YEAR(B5)=2018, 1.20530631312, 1)))))) -> 1.071612 | O5: =F5*N5 -> 230980.03 | P5: =O5 - H5 -> 219276.15 | Q5: =MIN(P5,G5) -> 219276.15 | R5: =IF(Q5<1000000,1,0) -> 1 | S5: =YEAR(B5) -> 2021
A6: CLM-00005 | B6: 45091 | C6: Injury to Third Parties | D6: 98692.46 | E6: In Litigation | F6: =D6+H6 -> 146820.18 | G6: 1000000 | H6: 48127.72 | I6: Human Error | J6: Indian Ocean | K6: Company 12 | L6: =IF(C6="Cargo Liability",RANDBETWEEN(10000,80000),IF(C6="Collision Liability",RANDBETWEEN(20000,100000),IF(C6="Environmental Pollution",RANDBETWEEN(50000,120000),IF(C6="Damage to Other Vessels",RANDBETWEEN(15000,90000),IF(C6="Injury to Third Parties",RANDBETWEEN(5000,60000)))))) -> 29590 | M6: 8 | N6: =IF(YEAR(B6)=2023, 1.03, IF(YEAR(B6)=2022, 1.0506, IF(YEAR(B6)=2021, 1.071612, IF(YEAR(B6)=2020, 1.10376036, IF(YEAR(B6)=2019, 1.1479107744, IF(YEAR(B6)=2018, 1.20530631312, 1)))))) -> 1.03 | O6: =F6*N6 -> 151224.79 | P6: =O6 - H6 -> 103097.07 | Q6: =MIN(P6,G6) -> 103097.07 | R6: =IF(Q6<1000000,1,0) -> 1 | S6: =YEAR(B6) -> 2023
A7: CLM-00006 | B7: 43584 | C7: Collision Liability | D7: 243918.65 | E7: Closed | F7: =D7+H7 -> 254504.19 | G7: 5000000 | H7: 10585.54 | I7: Technical Failure | J7: Atlantic Ocean | K7: Company 3 | L7: =IF(C7="Cargo Liability",RANDBETWEEN(10000,80000),IF(C7="Collision Liability",RANDBETWEEN(20000,100000),IF(C7="Environmental Pollution",RANDBETWEEN(50000,120000),IF(C7="Damage to Other Vessels",RANDBETWEEN(15000,90000),IF(C7="Injury to Third Parties",RANDBETWEEN(5000,60000)))))) -> 38359 | M7: 2 | N7: =IF(YEAR(B7)=2023, 1.03, IF(YEAR(B7)=2022, 1.0506, IF(YEAR(B7)=2021, 1.071612, IF(YEAR(B7)=2020, 1.10376036, IF(YEAR(B7)=2019, 1.1479107744, IF(YEAR(B7)=2018, 1.20530631312, 1)))))) -> 1.1479108 | O7: =F7*N7 -> 292148.1 | P7: =O7 - H7 -> 281562.56 | Q7: =MIN(P7,G7) -> 281562.56 | R7: =IF(Q7<1000000,1,0) -> 1 | S7: =YEAR(B7) -> 2019
A8: CLM-00007 | B8: 44398 | C8: Environmental Pollution | D8: 765873.46 | E8: Closed | F8: =D8+H8 -> 783218.83 | G8: 5000000 | H8: 17345.37 | I8: Natural Disaster | J8: North Sea | K8: Company 11 | L8: =IF(C8="Cargo Liability",RANDBETWEEN(10000,80000),IF(C8="Collision Liability",RANDBETWEEN(20000,100000),IF(C8="Environmental Pollution",RANDBETWEEN(50000,120000),IF(C8="Damage to Other Vessels",RANDBETWEEN(15000,90000),IF(C8="Injury to Third Parties",RANDBETWEEN(5000,60000)))))) -> 76741 | M8: 1 | N8: =IF(YEAR(B8)=2023, 1.03, IF(YEAR(B8)=2022, 1.0506, IF(YEAR(B8)=2021, 1.071612, IF(YEAR(B8)=2020, 1.10376036, IF(YEAR(B8)=2019, 1.1479107744, IF(YEAR(B8)=2018, 1.20530631312, 1)))))) -> 1.071612 | O8: =F8*N8 -> 839306.7 | P8: =O8 - H8 -> 821961.33 | Q8: =MIN(P8,G8) -> 821961.33 | R8: =IF(Q8<1000000,1,0) -> 1 | S8: =YEAR(B8) -> 2021
A9: CLM-00008 | B9: 44638 | C9: Damage to Other Vessels | D9: 913843.77 | E9: Closed | F9: =D9+H9 -> 939444.11 | G9: 5000000 | H9: 25600.34 | I9: Criminal Activity | J9: Atlantic Ocean | K9: Company 5 | L9: =IF(C9="Cargo Liability",RANDBETWEEN(10000,80000),IF(C9="Collision Liability",RANDBETWEEN(20000,100000),IF(C9="Environmental Pollution",RANDBETWEEN(50000,120000),IF(C9="Damage to Other Vessels",RANDBETWEEN(15000,90000),IF(C9="Injury to Third Parties",RANDBETWEEN(5000,60000)))))) -> 83478 | M9: 0 | N9: =IF(YEAR(B9)=2023, 1.03, IF(YEAR(B9)=2022, 1.0506, IF(YEAR(B9)=2021, 1.071612, IF(YEAR(B9)=2020, 1.10376036, IF(YEAR(B9)=2019, 1.1479107744, IF(YEAR(B9)=2018, 1.20530631312, 1)))))) -> 1.0506 | O9: =F9*N9 -> 986979.98 | P9: =O9 - H9 -> 961379.64 | Q9: =MIN(P9,G9) -> 961379.64 | R9: =IF(Q9<1000000,1,0) -> 1 | S9: =YEAR(B9) -> 2022
A10: CLM-00009 | B10: 44150 | C10: Cargo Liability | D10: 754890.21 | E10: Closed | F10: =D10+H10 -> 793074.65 | G10: 5000000 | H10: 38184.44 | I10: Technical Failure | J10: Mediterranean Sea | K10: Company 8 | L10: =IF(C10="Cargo Liability",RANDBETWEEN(10000,80000),IF(C10="Collision Liability",RANDBETWEEN(20000,100000),IF(C10="Environmental Pollution",RANDBETWEEN(50000,120000),IF(C10="Damage to Other Vessels",RANDBETWEEN(15000,90000),IF(C10="Injury to Third Parties",RANDBETWEEN(5000,60000)))))) -> 63327 | M10: 6 | N10: =IF(YEAR(B10)=2023, 1.03, IF(YEAR(B10)=2022, 1.0506, IF(YEAR(B10)=2021, 1.071612, IF(YEAR(B10)=2020, 1.10376036, IF(YEAR(B10)=2019, 1.1479107744, IF(YEAR(B10)=2018, 1.20530631312, 1)))))) -> 1.1037604 | O10: =F10*N10 -> 875364.36 | P10: =O10 - H10 -> 837179.92 | Q10: =MIN(P10,G10) -> 837179.92 | R10: =IF(Q10<1000000,1,0) -> 1 | S10: =YEAR(B10) -> 2020
A11: CLM-00010 | B11: 43258 | C11: Collision Liability | D11: 600293.27 | E11: Open | F11: =D11+H11 -> 601436.52 | G11: 5000000 | H11: 1143.25 | I11: Human Error | J11: Atlantic Ocean | K11: Company 10 | L11: =IF(C11="Cargo Liability",RANDBETWEEN(10000,80000),IF(C11="Collision Liability",RANDBETWEEN(20000,100000),IF(C11="Environmental Pollution",RANDBETWEEN(50000,120000),IF(C11="Damage to Other Vessels",RANDBETWEEN(15000,90000),IF(C11="Injury to Third Parties",RANDBETWEEN(5000,60000)))))) -> 28014 | M11: 5 | N11: =IF(YEAR(B11)=2023, 1.03, IF(YEAR(B11)=2022, 1.0506, IF(YEAR(B11)=2021, 1.071612, IF(YEAR(B11)=2020, 1.10376036, IF(YEAR(B11)=2019, 1.1479107744, IF(YEAR(B11)=2018, 1.20530631312, 1)))))) -> 1.2053063 | O11: =F11*N11 -> 724915.23 | P11: =O11 - H11 -> 723771.98 | Q11: =MIN(P11,G11) -> 723771.98 | R11: =IF(Q11<1000000,1,0) -> 1 | S11: =YEAR(B11) -> 2018
A12: CLM-00011 | B12: 44251 | C12: Environmental Pollution | D12: 320726.12 | E12: Closed | F12: =D12+H12 -> 363045.09 | G12: 5000000 | H12: 42318.97 | I12: Technical Failure | J12: North Sea | K12: Company 7 | L12: =IF(C12="Cargo Liability",RANDBETWEEN(10000,80000),IF(C12="Collision Liability",RANDBETWEEN(20000,100000),IF(C12="Environmental Pollution",RANDBETWEEN(50000,120000),IF(C12="Damage to Other Vessels",RANDBETWEEN(15000,90000),IF(C12="Injury to Third Parties",RANDBETWEEN(5000,60000)))))) -> 79002 | M12: 7 | N12: =IF(YEAR(B12)=2023, 1.03, IF(YEAR(B12)=2022, 1.0506, IF(YEAR(B12)=2021, 1.071612, IF(YEAR(B12)=2020, 1.10376036, IF(YEAR(B12)=2019, 1.1479107744, IF(YEAR(B12)=2018, 1.20530631312, 1)))))) -> 1.071612 | O12: =F12*N12 -> 389043.47 | P12: =O12 - H12 -> 346724.5 | Q12: =MIN(P12,G12) -> 346724.5 | R12: =IF(Q12<1000000,1,0) -> 1 | S12: =YEAR(B12) -> 2021
A13: CLM-00012 | B13: 44180 | C13: Cargo Liability | D13: 195238.55 | E13: Closed | F13: =D13+H13 -> 220873.24 | G13: 1000000 | H13: 25634.69 | I13: Criminal Activity | J13: Mediterranean Sea | K13: Company 6 | L13: =IF(C13="Cargo Liability",RANDBETWEEN(10000,80000),IF(C13="Collision Liability",RANDBETWEEN(20000,100000),IF(C13="Environmental Pollution",RANDBETWEEN(50000,120000),IF(C13="Damage to Other Vessels",RANDBETWEEN(15000,90000),IF(C13="Injury to Third Parties",RANDBETWEEN(5000,60000)))))) -> 69557 | M13: 8 | N13: =IF(YEAR(B13)=2023, 1.03, IF(YEAR(B13)=2022, 1.0506, IF(YEAR(B13)=2021, 1.071612, IF(YEAR(B13)=2020, 1.10376036, IF(YEAR(B13)=2019, 1.1479107744, IF(YEAR(B13)=2018, 1.20530631312, 1)))))) -> 1.1037604 | O13: =F13*N13 -> 243791.13 | P13: =O13 - H13 -> 218156.44 | Q13: =MIN(P13,G13) -> 218156.44 | R13: =IF(Q13<1000000,1,0) -> 1 | S13: =YEAR(B13) -> 2020
... A101: CLM-00100 | B101: 44922 | C101: Environmental Pollution | D101: 5000000 | E101: In Litigation | F101: =D101+H101 -> 5018723.8 | G101: 10000000 | H101: 18723.79 | I101: Natural Disaster | J101: Atlantic Ocean | K101: Company 15 | L101: =IF(C101="Cargo Liability",RANDBETWEEN(10000,80000),IF(C101="Collision Liability",RANDBETWEEN(20000,100000),IF(C101="Environmental Pollution",RANDBETWEEN(50000,120000),IF(C101="Damage to Other Vessels",RANDBETWEEN(15000,90000),IF(C101="Injury to Third Parties",RANDBETWEEN(5000,60000)))))) -> 80769 | M101: 9 | N101: =IF(YEAR(B101)=2023, 1.03, IF(YEAR(B101)=2022, 1.0506, IF(YEAR(B101)=2021, 1.071612, IF(YEAR(B101)=2020, 1.10376036, IF(YEAR(B101)=2019, 1.1479107744, IF(YEAR(B101)=2018, 1.20530631312, 1)))))) -> 1.0506 | O101: =F101*N101 -> 5272671.2 | P101: =O101 - H101 -> 5253947.4 | Q101: =MIN(P101,G101) -> 5253947.4 | R101: =IF(Q101<1000000,1,0) -> 0 | S101: =YEAR(B101) -> 2022

Sheet Exploratory Template
C2: Use pivot tables to generate tables and check for trends
K4: Loss location Summary
C5: Given Assumptions | K5: Net claims incurred by loss location
B6: 1 | C6: Commission is 0% | K6: Sum of Net inflation adjusted claim (HINT: Net inflation adjusted claim = Gross inflation adjusted claim - deductible) | L6: Column Labels
B7: 2 | C7: No adjustment is required for claims development patters | K7: Row Labels | L7: Atlantic Ocean | M7: Indian Ocean | N7: Mediterranean Sea | O7: North Sea | P7: Pacific Ocean | Q7: Grand Total
B8: 3 | C8: Individual policies run from 1/1 - 31/12 each year | K8: 2018 | L8: 2142028.4 | M8: 345659.15 | N8: 2089235.9 | O8: 1901894 | Q8: 6478817.3
K9: 2019 | L9: 3078681.3 | M9: 2703365.8 | N9: 1402178.8 | O9: 1650165.4 | P9: 1557588.5 | Q9: 10391980
K10: 2020 | L10: 2384580.5 | M10: 2791088.7 | N10: 3983656.4 | P10: 2913916.5 | Q10: 12073242
K11: 2021 | L11: 3164451.9 | M11: 1255557.6 | N11: 852809.66 | O11: 1785612.8 | P11: 4907895.5 | Q11: 11966327
C12: Average Gross Claim Amount | K12: 2022 | L12: 7283308.6 | M12: 1673107.9 | N12: 3625547.2 | O12: 1703600.6 | P12: 720119.69 | Q12: 15005684
C13: =AVERAGE('Claims Data'!F2:F1010) -> 606718.31 | K13: 2023 | L13: 1459094.7 | M13: 103097.07 | N13: 816921.86 | O13: 3629817.9 | P13: 1436945.9 | Q13: 7445877.4
K14: Grand Total | L14: 19512145 | M14: 8871876.2 | N14: 12770350 | O14: 10671091 | P14: 11536466 | Q14: 63361928
C15: Average Claim Amount (Adjusted for Inflation)
C16: =AVERAGE('Claims Data'!O2:O101) -> 662235.24 | K16: Claim count by loss location
K17: Count of Location | L17: Column Labels
C18: Average Claim Amount by Year (Adjusted for Inflation) | K18: Row Labels | L18: Atlantic Ocean | M18: Indian Ocean | N18: Mediterranean Sea | O18: North Sea | P18: Pacific Ocean | Q18: Grand Total
K19: 2018 | L19: 3 | M19: 1 | N19: 3 | O19: 3 | Q19: 10
C20: Row Labels | D20: Average of Gross inflation adjusted claim (HINT: Gross inflation adjusted claim = gross claim * inflation index) | K20: 2019 | L20: 5 | M20: 5 | N20: 2 | O20: 3 | P20: 2 | Q20: 17
C21: 2018 | D21: 669173.2 | K21: 2020 | L21: 4 | M21: 4 | N21: 6 | P21: 6 | Q21: 20
C22: 2019 | D22: 639793 | K22: 2021 | L22: 5 | M22: 3 | N22: 1 | O22: 3 | P22: 8 | Q22: 20
C23: 2020 | D23: 636678.23 | K23: 2022 | L23: 4 | M23: 4 | N23: 5 | O23: 3 | P23: 1 | Q23: 17
C24: 2021 | D24: 626237.13 | K24: 2023 | L24: 2 | M24: 1 | N24: 2 | O24: 8 | P24: 3 | Q24: 16
C25: 2022 | D25: 911278.74 | K25: Grand Total | L25: 23 | M25: 18 | N25: 19 | O25: 20 | P25: 20 | Q25: 100
C26: 2023 | D26: 494079.09
C27: Grand Total | D27: 662235.24 | K27: Average claim cost by loss location (severity)
K28: Average of Net inflation adjusted claim (HINT: Net inflation adjusted claim = Gross inflation adjusted claim - deductible) | L28: Column Labels
K29: Row Labels | L29: Atlantic Ocean | M29: Indian Ocean | N29: Mediterranean Sea | O29: North Sea | P29: Pacific Ocean | Q29: Grand Total
C30: Claim Type Summary | K30: 2018 | L30: 714009.45 | M30: 345659.15 | N30: 696411.95 | O30: 633964.65 | Q30: 647881.73
C31: Net claims incurred by claim type | K31: 2019 | L31: 615736.25 | M31: 540673.17 | N31: 701089.41 | O31: 550055.14 | P31: 778794.26 | Q31: 611292.93
C32: Sum of Net inflation adjusted claim (HINT: Net inflation adjusted claim = Gross inflation adjusted claim - deductible) | D32: Column Labels | K32: 2020 | L32: 596145.14 | M32: 697772.18 | N32: 663942.74 | P32: 485652.75 | Q32: 603662.11
C33: Row Labels | D33: Cargo Liability | E33: Collision Liability | F33: Damage to Other Vessels | G33: Environmental Pollution | H33: Injury to Third Parties | I33: Grand Total | K33: 2021 | L33: 632890.37 | M33: 418519.19 | N33: 852809.66 | O33: 595204.27 | P33: 613486.93 | Q33: 598316.37
C34: 2018 | D34: 697368.02 | E34: 2405966.1 | F34: 1375285.3 | H34: 2000197.9 | I34: 6478817.3 | K34: 2022 | L34: 1820827.1 | M34: 418276.97 | N34: 725109.45 | O34: 567866.88 | P34: 720119.69 | Q34: 882687.3
C35: 2019 | D35: 662834.33 | E35: 3253999.9 | F35: 2434672.4 | G35: 3215152.3 | H35: 825320.96 | I35: 10391980 | K35: 2023 | L35: 729547.33 | M35: 103097.07 | N35: 408460.93 | O35: 453727.24 | P35: 478981.96 | Q35: 465367.34
C36: 2020 | D36: 3570921.3 | F36: 3050494.7 | G36: 3693140.9 | H36: 1758685.2 | I36: 12073242 | K36: Grand Total | L36: 848354.14 | M36: 492882.01 | N36: 672123.68 | O36: 533554.54 | P36: 576823.3 | Q36: 633619.28
C37: 2021 | D37: 1781773.2 | E37: 4027741.5 | F37: 2386006.6 | G37: 3537852.8 | H37: 232953.22 | I37: 11966327
C38: 2022 | D38: 2937526.7 | E38: 997566.68 | F38: 2654253.8 | G38: 8416336.8 | I38: 15005684
C39: 2023 | D39: 1570662.9 | E39: 1410599.6 | F39: 834871.47 | H39: 3629743.5 | I39: 7445877.4 | K39: Add some useful charts
C40: Grand Total | D40: 11221086 | E40: 12095874 | F40: 12735584 | G40: 18862483 | H40: 8446900.9 | I40: 63361928 | K40: HINT: Net incurred claims by year and claim type
K41: HINT: Count of claims by year and claim type
C42: Claim count by claim type
...

Sheet Pure Premium Work
G1: Claim frequency per gross tonnage
B2: Inflation Indices (Assumed for the Purpose of This Exercise): | G2: 1 | H2: Calculate the Loss Frequency using a pivot table, make sure to remove the large loss event. Claim frequency = Number of Claims/Gross Tonnage for all exposure.
D4: (1 + annual inflation) | E4: Inflation index | G4: Year | H4: Gross tonnage for all exposure | I4: No of claims | J4: Claim frequency per unit of gross tonnage
B5: 2018 | C5: 1.08 (8% inflation) | D5: 1.08 | E5: =E6*D6 -> 1.2053063 | G5: 2018 | H5: =C15 -> 45000000 | I5: =COUNTIFS('Claims Data'!$D$2:$D$101, "<1000000",'Claims Data'!$S$2:$S$101,'Pure Premium Work'!G5) -> 10 | J5: =I5/H5 -> 2.2222222e-07
B6: 2019 | C6: 1.05 (5% inflation) | D6: 1.05 | E6: =E7*D7 -> 1.1479108 | G6: =G5+1 -> 2019 | H6: =C16 -> 49000000 | I6: =COUNTIFS('Claims Data'!$D$2:$D$101, "<1000000",'Claims Data'!$S$2:$S$101,'Pure Premium Work'!G6) -> 17 | J6: =I6/H6 -> 3.4693878e-07
B7: 2020 | C7: 1.04 (4% inflation) | D7: 1.04 | E7: =E8*D8 -> 1.1037604 | G7: =G6+1 -> 2020 | H7: =C17 -> 41750000 | I7: =COUNTIFS('Claims Data'!$D$2:$D$101, "<1000000",'Claims Data'!$S$2:$S$101,'Pure Premium Work'!G7) -> 20 | J7: =I7/H7 -> 4.7904192e-07
B8: 2021 | C8: 1.03 (3% inflation) | D8: 1.03 | E8: =E9*D9 -> 1.071612 | G8: =G7+1 -> 2021 | H8: =C18 -> 41500000 | I8: =COUNTIFS('Claims Data'!$D$2:$D$101, "<1000000",'Claims Data'!$S$2:$S$101,'Pure Premium Work'!G8) -> 20 | J8: =I8/H8 -> 4.8192771e-07
B9: 2022 | C9: 1.02 (2% inflation) | D9: 1.02 | E9: =E10*D10 -> 1.0506 | G9: =G8+1 -> 2022 | H9: =C19 -> 43590000 | I9: =COUNTIFS('Claims Data'!$D$2:$D$101, "<1000000",'Claims Data'!$S$2:$S$101,'Pure Premium Work'!G9) -> 16 | J9: =I9/H9 -> 3.6705666e-07
B10: 2023 | C10: 1.02 (2% inflation) | D10: 1.02 | E10: =E11*D11 -> 1.03 | G10: =G9+1 -> 2023 | H10: =C20 -> 44750000 | I10: =COUNTIFS('Claims Data'!$D$2:$D$101, "<1000000",'Claims Data'!$S$2:$S$101,'Pure Premium Work'!G10) -> 16 | J10: =I10/H10 -> 3.575419e-07
B11: 2024 | C11: 1.03 (3% expected over year) | D11: 1.03 | E11: 1
G12: Claim severity analysis (average cost per claim)
B13: Exposure information for the account provided by client | G13: 2 | H13: Calculate the Average cost per claim (Loss Severity) using a pivot table, make sure to remove the large loss event. Instructions: Create a pivot table with Year, Sum of Capped net inflation adjusted incurred claim and Count of Claim ID. Loss Severity= Sum of Capped net inflation adjusted incurred claim / Count of Claim ID for each year.
B14: Year | C14: Gross tonnage
B15: 2018 | C15: =45000000 -> 45000000
B16: =B15+1 -> 2019 | C16: 49000000
B17: =B16+1 -> 2020 | C17: 41750000 | G17: Year | H17: Sum of Capped net inflation adjusted incurred claim | I17: No of claims | J17: Loss Severity
B18: =B17+1 -> 2021 | C18: 41500000 | G18: 2018 | H18: =SUMIFS('Claims Data'!$Q$2:$Q$101,'Claims Data'!$Q$2:$Q$101,"<1000000",'Claims Data'!$S$2:$S$101,'Pure Premium Work'!G18) -> 6428231.6 | I18: =COUNTIFS('Claims Data'!$Q$2:$Q$101,"<1000000",'Claims Data'!$S$2:$S$101,'Pure Premium Work'!G18) -> 10 | J18: =H18/I18 -> 642823.16
B19: =B18+1 -> 2022 | C19: 43590000 | G19: =G18+1 -> 2019 | H19: =SUMIFS('Claims Data'!$Q$2:$Q$101,'Claims Data'!$Q$2:$Q$101,"<1000000",'Claims Data'!$S$2:$S$101,'Pure Premium Work'!G19) -> 10365189 | I19: =COUNTIFS('Claims Data'!$Q$2:$Q$101,"<1000000",'Claims Data'!$S$2:$S$101,'Pure Premium Work'!G19) -> 17 | J19: =H19/I19 -> 609716.99
B20: =B19+1 -> 2023 | C20: 44750000 | G20: =G19+1 -> 2020 | H20: =SUMIFS('Claims Data'!$Q$2:$Q$101,'Claims Data'!$Q$2:$Q$101,"<1000000",'Claims Data'!$S$2:$S$101,'Pure Premium Work'!G20) -> 12073242 | I20: =COUNTIFS('Claims Data'!$Q$2:$Q$101,"<1000000",'Claims Data'!$S$2:$S$101,'Pure Premium Work'!G20) -> 20 | J20: =H20/I20 -> 603662.11
G21: =G20+1 -> 2021 | H21: =SUMIFS('Claims Data'!$Q$2:$Q$101,'Claims Data'!$Q$2:$Q$101,"<1000000",'Claims Data'!$S$2:$S$101,'Pure Premium Work'!G21) -> 11966327 | I21: =COUNTIFS('Claims Data'!$Q$2:$Q$101,"<1000000",'Claims Data'!$S$2:$S$101,'Pure Premium Work'!G21) -> 20 | J21: =H21/I21 -> 598316.37
B22: 2024 expected gross tonnage provided by client | C22: 40000000 | G22: =G21+1 -> 2022 | H22: =SUMIFS('Claims Data'!$Q$2:$Q$101,'Claims Data'!$Q$2:$Q$101,"<1000000",'Claims Data'!$S$2:$S$101,'Pure Premium Work'!G22) -> 9751736.6 | I22: =COUNTIFS('Claims Data'!$Q$2:$Q$101,"<1000000",'Claims Data'!$S$2:$S$101,'Pure Premium Work'!G22) -> 16 | J22: =H22/I22 -> 609483.54
G23: =G22+1 -> 2023 | H23: =SUMIFS('Claims Data'!$Q$2:$Q$101,'Claims Data'!$Q$2:$Q$101,"<1000000",'Claims Data'!$S$2:$S$101,'Pure Premium Work'!G23) -> 7445877.4 | I23: =COUNTIFS('Claims Data'!$Q$2:$Q$101,"<1000000",'Claims Data'!$S$2:$S$101,'Pure Premium Work'!G23) -> 16 | J23: =H23/I23 -> 465367.34
C24: Given Assumptions
B25: 1 | C25: Commission is 0%
B26: 2 | C26: No adjustment is required for claims development patters
B27: 3 | C27: Deductibles in the upcoming policy period will be the same as deductible in prior policy periods. | G27: Loss cost calculation
B28: 4 | C28: Individual policies run from 1/1 - 31/12 each year | G28: 3 | H28: Complete the table below using the values derived in steps 1 and 2. HINT: Expected loss is the product of claim frequency and average claim severity.
B29: 5 | C29: Assume a large loss is any loss >$1m incurred
B30: 6 | C30: Assume the large loss event is a 1-in-20 year event. | G30: Loss cost | H30: Average cost per claim (Loss Severity) | I30: Claim frequency per unit of gross tonnage | J30: Expected loss per unit of gross tonnage
B31: 7 | C31: Assume expenses are 30% of the loss cost. | G31: 2018 | H31: =J18 -> 642823.16 | I31: =J5 -> 2.2222222e-07 | J31: =H31*I31 -> 0.14284959
B32: 8 | C32: Assume a 10% profit requirement on this account in calculating the premium | G32: 2019 | H32: =J19 -> 609716.99 | I32: =J6 -> 3.4693878e-07 | J32: =H32*I32 -> 0.21153447
G33: 2020 | H33: =J20 -> 603662.11 | I33: =J7 -> 4.7904192e-07 | J33: =H33*I33 -> 0.28917945
G34: 2021 | H34: =J21 -> 598316.37 | I34: =J8 -> 4.8192771e-07 | J34: =H34*I34 -> 0.28834524
G35: 2022 | H35: =J22 -> 609483.54 | I35: =J9 -> 3.6705666e-07 | J35: =H35*I35 -> 0.22371499
G36: 2023 | H36: =J23 -> 465367.34 | I36: =J10 -> 3.575419e-07 | J36: =H36*I36 -> 0.16638832
A37: 5 | B37: Identify the Large Loss Event adjusted for inflation.
B38: Large Loss Event | G38: 4 | H38: Calculate the following using the values derived in step 3.
B39: ='Claims Data'!P101 -> 5253947.4
A41: 6 | B41: Derive an appropriate Return Period. (Consider the information provided in the "Given Assumptions"). | G41: Average frequency per unit exposure | H41: =SUM(I5:I10)/SUM(H5:H10) -> 3.72755e-07
B42: Return Period | G42: Average severity per claim | H42: =SUM(H18:H23)/SUM(I18:I23) -> 586167.72
...

Sheet Stress Testing
G1: Claim frequency per gross tonnage
B2: Inflation Indices (Assumed for the Purpose of This Exercise): | G2: 1 | H2: Calculate the Loss Frequency using a pivot table, make sure to remove the large loss event. Claim frequency = Number of Claims/Gross Tonnage for all exposure.
D4: (1 + annual inflation) | E4: Inflation index | G4: Year | H4: Gross tonnage for all exposure | I4: No of claims | J4: Claim frequency per unit of gross tonnage
B5: 2018 | C5: 1.08 (8% inflation) | D5: 1.08 | E5: =E6*D6 -> 1.2053063 | G5: 2018 | H5: =C15 -> 45000000 | I5: =COUNTIFS('Claims Data'!$D$2:$D$101, "<1000000",'Claims Data'!$S$2:$S$101,'Stress Testing'!G5) -> 10 | J5: =I5/H5 -> 2.2222222e-07
B6: 2019 | C6: 1.05 (5% inflation) | D6: 1.05 | E6: =E7*D7 -> 1.1479108 | G6: =G5+1 -> 2019 | H6: =C16 -> 49000000 | I6: =COUNTIFS('Claims Data'!$D$2:$D$101, "<1000000",'Claims Data'!$S$2:$S$101,'Stress Testing'!G6) -> 17 | J6: =I6/H6 -> 3.4693878e-07
B7: 2020 | C7: 1.04 (4% inflation) | D7: 1.04 | E7: =E8*D8 -> 1.1037604 | G7: =G6+1 -> 2020 | H7: =C17 -> 41750000 | I7: =COUNTIFS('Claims Data'!$D$2:$D$101, "<1000000",'Claims Data'!$S$2:$S$101,'Stress Testing'!G7) -> 20 | J7: =I7/H7 -> 4.7904192e-07
B8: 2021 | C8: 1.03 (3% inflation) | D8: 1.03 | E8: =E9*D9 -> 1.071612 | G8: =G7+1 -> 2021 | H8: =C18 -> 41500000 | I8: =COUNTIFS('Claims Data'!$D$2:$D$101, "<1000000",'Claims Data'!$S$2:$S$101,'Stress Testing'!G8) -> 20 | J8: =I8/H8 -> 4.8192771e-07
B9: 2022 | C9: 1.02 (2% inflation) | D9: 1.02 | E9: =E10*D10 -> 1.0506 | G9: =G8+1 -> 2022 | H9: =C19 -> 43590000 | I9: =COUNTIFS('Claims Data'!$D$2:$D$101, "<1000000",'Claims Data'!$S$2:$S$101,'Stress Testing'!G9) -> 16 | J9: =I9/H9 -> 3.6705666e-07
B10: 2023 | C10: 1.02 (2% inflation) | D10: 1.02 | E10: =E11*D11 -> 1.03 | G10: =G9+1 -> 2023 | H10: =C20 -> 44750000 | I10: =COUNTIFS('Claims Data'!$D$2:$D$101, "<1000000",'Claims Data'!$S$2:$S$101,'Stress Testing'!G10) -> 16 | J10: =I10/H10 -> 3.575419e-07
B11: 2024 | C11: 1.03 (3% expected over year) | D11: 1.03 | E11: 1
G12: Claim severity analysis (average cost per claim)
B13: Exposure information for the account provided by client | G13: 2 | H13: Calculate the Average cost per claim (Loss Severity) using a pivot table, make sure to remove the large loss event. Instructions: Create a pivot table with Year, Sum of Capped net inflation adjusted incurred claim and Count of Claim ID. Loss Severity= Sum of Capped net inflation adjusted incurred claim / Count of Claim ID for each year.
B14: Year | C14: Gross tonnage
B15: 2018 | C15: =45000000 -> 45000000
B16: =B15+1 -> 2019 | C16: 49000000
B17: =B16+1 -> 2020 | C17: 41750000 | G17: Year | H17: Sum of Capped net inflation adjusted incurred claim | I17: No of claims | J17: Loss Severity
B18: =B17+1 -> 2021 | C18: 41500000 | G18: 2018 | H18: =SUMIFS('Claims Data'!$Q$2:$Q$101,'Claims Data'!$Q$2:$Q$101,"<1000000",'Claims Data'!$S$2:$S$101,'Stress Testing'!G18)*(1+0.06) -> 6813925.5 | I18: =COUNTIFS('Claims Data'!$Q$2:$Q$101,"<1000000",'Claims Data'!$S$2:$S$101,'Stress Testing'!G18) -> 10 | J18: =H18/I18 -> 681392.55
B19: =B18+1 -> 2022 | C19: 43590000 | G19: =G18+1 -> 2019 | H19: =SUMIFS('Claims Data'!$Q$2:$Q$101,'Claims Data'!$Q$2:$Q$101,"<1000000",'Claims Data'!$S$2:$S$101,'Stress Testing'!G19)*(1+0.06) -> 10987100 | I19: =COUNTIFS('Claims Data'!$Q$2:$Q$101,"<1000000",'Claims Data'!$S$2:$S$101,'Stress Testing'!G19) -> 17 | J19: =H19/I19 -> 646300.01
B20: =B19+1 -> 2023 | C20: 44750000 | G20: =G19+1 -> 2020 | H20: =SUMIFS('Claims Data'!$Q$2:$Q$101,'Claims Data'!$Q$2:$Q$101,"<1000000",'Claims Data'!$S$2:$S$101,'Stress Testing'!G20)*(1+0.06) -> 12797637 | I20: =COUNTIFS('Claims Data'!$Q$2:$Q$101,"<1000000",'Claims Data'!$S$2:$S$101,'Stress Testing'!G20) -> 20 | J20: =H20/I20 -> 639881.84
G21: =G20+1 -> 2021 | H21: =SUMIFS('Claims Data'!$Q$2:$Q$101,'Claims Data'!$Q$2:$Q$101,"<1000000",'Claims Data'!$S$2:$S$101,'Stress Testing'!G21)*(1+0.06) -> 12684307 | I21: =COUNTIFS('Claims Data'!$Q$2:$Q$101,"<1000000",'Claims Data'!$S$2:$S$101,'Stress Testing'!G21) -> 20 | J21: =H21/I21 -> 634215.35
B22: 2024 expected gross tonnage provided by client | C22: 40000000 | G22: =G21+1 -> 2022 | H22: =SUMIFS('Claims Data'!$Q$2:$Q$101,'Claims Data'!$Q$2:$Q$101,"<1000000",'Claims Data'!$S$2:$S$101,'Stress Testing'!G22)*(1+0.06) -> 10336841 | I22: =COUNTIFS('Claims Data'!$Q$2:$Q$101,"<1000000",'Claims Data'!$S$2:$S$101,'Stress Testing'!G22) -> 16 | J22: =H22/I22 -> 646052.55
G23: =G22+1 -> 2023 | H23: =SUMIFS('Claims Data'!$Q$2:$Q$101,'Claims Data'!$Q$2:$Q$101,"<1000000",'Claims Data'!$S$2:$S$101,'Stress Testing'!G23)*(1+0.06) -> 7892630.1 | I23: =COUNTIFS('Claims Data'!$Q$2:$Q$101,"<1000000",'Claims Data'!$S$2:$S$101,'Stress Testing'!G23) -> 16 | J23: =H23/I23 -> 493289.38
C24: Given Assumptions
B25: 1 | C25: Commission is 0%
B26: 2 | C26: No adjustment is required for claims development patters
B27: 3 | C27: Deductibles in the upcoming policy period will be the same as deductible in prior policy periods. | G27: Loss cost calculation
B28: 4 | C28: Individual policies run from 1/1 - 31/12 each year | G28: 3 | H28: Complete the table below using the values derived in steps 1 and 2. HINT: Expected loss is the product of claim frequency and average claim severity.
B29: 5 | C29: Assume a large loss is any loss >$1m incurred
B30: 6 | C30: Assume the large loss event is a 1-in-20 year event. | G30: Loss cost | H30: Average cost per claim (Loss Severity) | I30: Claim frequency per unit of gross tonnage | J30: Expected loss per unit of gross tonnage
B31: 7 | C31: Assume expenses are 30% of the loss cost. | G31: 2018 | H31: =J18 -> 681392.55 | I31: =J5 -> 2.2222222e-07 | J31: =H31*I31 -> 0.15142057
B32: 8 | C32: Assume a 10% profit requirement on this account in calculating the premium | G32: 2019 | H32: =J19 -> 646300.01 | I32: =J6 -> 3.4693878e-07 | J32: =H32*I32 -> 0.22422654
G33: 2020 | H33: =J20 -> 639881.84 | I33: =J7 -> 4.7904192e-07 | J33: =H33*I33 -> 0.30653022
G34: 2021 | H34: =J21 -> 634215.35 | I34: =J8 -> 4.8192771e-07 | J34: =H34*I34 -> 0.30564595
G35: 2022 | H35: =J22 -> 646052.55 | I35: =J9 -> 3.6705666e-07 | J35: =H35*I35 -> 0.23713789
G36: 2023 | H36: =J23 -> 493289.38 | I36: =J10 -> 3.575419e-07 | J36: =H36*I36 -> 0.17637162
A37: 5 | B37: Identify the Large Loss Event adjusted for inflation.
B38: Large Loss Event | G38: 4 | H38: Calculate the following using the values derived in step 3.
B39: ='Claims Data'!P101 -> 5253947.4
A41: 6 | B41: Derive an appropriate Return Period. (Consider the information provided in the "Given Assumptions"). | G41: Average frequency per unit exposure | H41: =SUM(I5:I10)/SUM(H5:H10) -> 3.72755e-07
B42: Return Period | G42: Average severity per claim | H42: =SUM(H18:H23)/SUM(I18:I23) -> 621337.78
...

Sheet Report
